Workbook

Sheet DASHBOARD
A1: BUSINESS DEVELOPMENT ACTIVITIES DASHBOARD | D1: New Business 2026
H2: $US Conv.
A3: REGION | B3: Activities | C3: Total Proposals Submitted $Cdn | D3: Proposals Submitted $USD | E3: Total Proposals Accepted $Cdn | F3: Proposals Accepted $USD | G3: Capture Rate %
A5: Vancouver; Lower Mainland | B5: ='Vancouver; Lower Mainland'!A25 -> 19 | C5: ='Vancouver; Lower Mainland'!J25 -> 905000 | E5: ='Vancouver; Lower Mainland'!K25 -> 610000 | G5: =E5/C5 -> 0.67403315
A6: Vancouver Island | B6: ='Vancouver Island'!A7 -> 1 | C6: ='Vancouver Island'!J7 -> 0.01 | E6: ='Vancouver Island'!K7 -> 0 | G6: =E6/C6 -> 0
A7: Okanagan; BC Interior | B7: ='Okanagan; BC Interior'!A20 -> 15 | C7: ='Okanagan; BC Interior'!J20 -> 461000 | E7: ='Okanagan; BC Interior'!K20 -> 91000 | G7: =E7/C7 -> 0.19739696
A8: Alberta | B8: =Alberta!A37 -> 0 | C8: =Alberta!J37 -> 798000 | E8: =Alberta!K37 -> 0 | G8: =E8/C8 -> 0
A9: Eastern Canada | B9: ='Eastern Canada'!A7 -> 1 | C9: ='Eastern Canada'!J7 -> 0.01 | E9: ='Eastern Canada'!K7 -> 0 | G9: =E9/C9 -> 0
A10: USA | B10: =USA!A23 -> 17 | C10: =D10*H10 -> 2022320 | D10: =USA!K23 -> 1487000 | E10: =F10*H10 -> 0 | F10: =USA!L23 -> 0 | G10: =E10/C10 -> 0 | H10: 1.36
A12: TOTALS | B12: =SUM(B5:B11) -> 53 | C12: =SUM(C5:C11) -> 4186320 | D12: =SUM(D5:D11) -> 1487000 | E12: =SUM(E5:E11) -> 701000 | F12: =SUM(F5:F11) -> 0 | G12: =E12/C12 -> 0.16745017
A17: Meeting Notes:
A19: BD Strategy mtg 2026-04-10 | B19: Regional BD Managers identified for each of the follow regions:
C20: Van / Lower Mainland - Omar
C21: Victoria - Rory
C22: Alberta - Islam
C23: Okanagan - Conor
C24: USA - Jim
B25: Each regional manager will be responsible to facilitate BD efforts and coordinate with other client facing partners for support and keep the BD Activities spreadsheet up to date.
B26: Islam wil be assigned the title of "Alberta Regional Manager"
B27: We should make an announcement of Islam joining as regional manager in Alberta (6 month Non-comp clause from Intuitive)
B28: No special title will be assigned at this time for the other regional BD managers
B29: Each region will be listed on all email signatures and on the website for promotion
B30: Website requires updating:
C31: Website is a promotional tool and should only have info on it that helps us.
C32: Staff should be removed from the website
C33: update to include each region including a list of projects
C34: The map is clunky and needs updating.
B35: We should increase our profile on LinkIn
B36: Qualifications brochures and other smaller brochures should be vetted and made available to all parties.
B37: We are planning to arrange a promotional trip to Alberta (Edmonton & Calgary for May 6,7,8 - to be confirmed.
B38: Followup Full BD meeting with all parties including other client facing staff and partners to occur after the Alberta promo trip.

Sheet Vancouver; Lower Mainland
A1: Business Development Acitivities Log - VANCOUVER
A3: No. | B3: Date | C3: Initiator | D3: Contact | E3: Company | F3: Contact Info | G3: Location | H3: Type | I3: Potential Projects | J3: Proposals Submitted | K3: Proposals Accepted $ | L3: Notes
A4: 1 | B4: 45666 | C4: Omar ALcazar | D4: Hamid Ahmandia | E4: Areva Living | F4: Hamid@Arevaliving.com | G4: Vancouver | H4: Meeting | I4: 2 - rental towers in New west. | J4: 200000 | K4: 200000 | L4: Met Hammid at a UDI tour for Meridian, Follow up with the new code presentation. We got an RFP for one of their rental towers in New West and we were selected as the structural consultants. There is another tower at the early stages that is on hold.
A5: 2 | B5: 45728 | C5: Omar ALcazar | D5: Jason Ha | E5: Concord Pacifid | G5: Vancouver | H5: Meeting | I5: Potential towers, vancouvre, surrey and Calgary | L5: We were introduce to Jason Ha ( Vp of construction ) of Concord pacific by John from Allure. We have provided good services for all theird projects, even urgent requests for inspections and even respond to late night and weekend phone calls. ( the service we are providing and helping them to get OP 6 months a head of schedule help pursuing them to give us an intro to concord pacifid)
A6: 3 | B6: 45966 | C6: Omar ALcazar | D6: Sukhi Raj | E6: RBI group | F6: sukhi@rbigroup.ca | G6: Vancouver | H6: Meeting | I6: New hotels all over Lower Mainland | J6: 530000 | K6: 300000 | L6: Already got awarded a hotel/residential tower in surrey. Pursuing the Hotel at Main and Prior street.( New client that bought and existing hotel. Came to the office for input on how to save money. We provided a new scheme and several options. We provided services beypond of what he was expecting. Sukhi wants to work with us.
A7: 4 | B7: 46065 | C7: Omar Alcazar | D7: Grant Myles | E7: Grosvenor | G7: Vancouver | H7: Phone Call | I7: possible tilt-up | L7: I got the contact information from a site super that use to work with him and knows him well from Peter wall
A8: 5 | B8: 46002 | C8: Omar Alcazar | D8: Dev Sharma | E8: Shape properties | G8: Vancouver | H8: Phone Call | L8: Need to follow up with a phone call
A9: 6 | B9: 45975 | C9: Conor Murtagh | D9: Patrick Li | E9: Enso Group | F9: pli@enso-group.ca | G9: Vancouver | H9: Meeting | I9: Surrey Midrise | J9: 65000 | L9: Conor & JM met Patrick for coffee.
A10: 7 | B10: 45981 | C10: Omar Alcazar | D10: Ben Omidvar | E10: ForteLiving | G10: Vancouver | H10: Event | I10: towers and wood frame | L10: Met him at an ULI event at the end of the year
A11: 8 | B11: 45909 | C11: Omar Alcazar | D11: Matthew Cavanaugh | E11: Cadillac Fairview | G11: Vancouver | H11: Event | I11: comercial/residencial projects | L11: Met him at an UDI breakfast presentaiton- need to follow up. They are teeming up with SHape
A12: 9 | B12: 46045 | C12: Conor Murtagh | D12: Jonathon Silcock | E12: Denciti Development | F12: jsilcock@denciti.ca | G12: Vancouver | H12: Meeting | L12: Conor & JM met Jonathon for lunch.
A13: 10 | B13: 46078 | C13: Jim DesRoches | D13: Mike De Cotiis | E13: Pinnacle Development | F13: md@pinnacleinternational.ca | G13: San Diego | H13: California | L13: Reached out to invite Mike to dinner in San Diego week of Mar 3, Jim Ralph told me that Pinnacle has several new sites in San Diego, plan to discuss KOR expansion to Alberta and followup on new work in Vancouver.
A14: 11 | B14: 46083 | C14: Conor Murtagh | D14: Cellina Heang | E14: Makola Development Services | F14: cheang@makoladev.com | G14: Vancouver | H14: Phone Call | L14: Submitted proposal for review of RJC's work on daycare. Proposal rejected but they will look to us for new work in future.
A15: 12 | B15: 46108 | C15: Conor Murtagh | D15: Jeff Fong/Darren Rae | E15: Qualico/Streetside BC | F15: Jeff.fong@qualico.com / Darren.Rae@qualico.com | G15: Surrey | H15: Meeting | L15: Conor & JM met Jeff and Darren for lunch in cloverdale.
A16: 13 | B16: 46107 | C16: Jim DesRoches | D16: Freddy Pina | E16: PBRV Consulting | F16: fpina@pbrvconsulting.com | G16: Vancouver | H16: Presentation | L16: PBD Presentation for Lecture to Structural Engineering class. Structural Engineering Association of BC: Certificate in Structural Engineering Program E23 Performance Based Seismic Design of Buildings
A17: 14 | B17: 46118 | C17: Conor Murtagh | D17: Kyle Foot | E17: Purpose Driven | F17: kyle@purposedrivenroi.com | G17: Vancouver | H17: Email | I17: Epiphany Church Surrey | J17: 110000 | K17: 110000 | L17: Organising lunch with Purpose Driven that Conor, JM, Andrea nad Kate will attend.
A18: 15 | B18: 45980 | C18: Omar Alcazar | D18: Hans Fast | E18: Fastmark | F18: hans@fastmark.ca | G18: Vancouver | H18: Meeting | I18: towers and wood frame | L18: I was introduce to Hans by a PM from Axiom- I got his contact info and set up a meeting. most of the thier work will go to Fast& Epp but they are willing to try us. Broadway projects currently on hold
A19: 16 | B19: 46120 | C19: Omar Alcazar | D19: Tanner Younghans | E19: A&H steel | F19: tannery@ah-steel.com | G19: Vancouver | H19: Meeting | I19: possible tilt-up and wind turbine
A20: 17 | B20: 45618 | C20: Omar Alcazar | D20: Brad Howard | E20: PCI Development | G20: Vanvouver | H20: Phone Call | L20: Need to follow up with a phone call
A21: 18 | B21: 46133 | C21: Omar Alcazar | D21: Anneliese Neweduk | E21: M'akola Development | G21: Vanouuver | H21: Event | I21: towers and wood frames | L21: Meet Anneliese at a ULI event- will call her a set up a meeting
A22: 19 | B22: 46133 | C22: Omar Alcazar | D22: Kendall Andison | E22: CIty Spaces consulting | G22: Vanouuver | H22: Event | I22: towers and wood frames | L22: Meet Anneliese at a ULI event- will call her a set up a meeting
A24: TOTALS
A25: =A22 -> 19 | J25: =SUM(J4:J22) -> 905000 | K25: =SUM(K4:K22) -> 610000
A32: PENDING people to contact
B33: 45876 | C33: Omar Alcazar | D33: Abhishek Chaun | E33: PC Urban | G33: Vancouver | I33: towers | L33: Trying to set up a meeting with PC Urban development team
B34: 45722 | C34: Omar ALcazar | D34: Ryan Lee | E34: Landa Global | G34: Vancoucer | I34: towers | L34: Trying to set up a meeting with PC Urban development team
B35: 46058 | C35: Omar Alcazar | D35: Manit Saiyah | E35: ITC | G35: Vancouver | I35: projects with CHARD development | L35: I know Manit since he was in Thind Properties- He is at ITC and is recommendign as for projects with CHARD , he is going to try o set up a meetign with Chard's development team
C36: Omar ALcazar | D36: David Shamash | G36: Vancouver | L36: I know him becuase our kids go to the same school- trying to get the contact info for Concert Properties.

Sheet Vancouver Island
A1: Business Development Acitivities Log - VANCOUVER ISLAND
A3: No. | B3: Date | C3: Initiator | D3: Contact | E3: Company | F3: Contact Info | G3: Location | H3: Type | I3: Potential Projects | J3: Proposals Submitted | K3: Proposals Accepted $ | L3: Notes
A4: 1 | J4: 0.01 | K4: 0
A6: TOTALS
A7: =A4 -> 1 | J7: =SUM(J4:J6) -> 0.01 | K7: =SUM(K4:K6) -> 0

Sheet USA
A1: Business Development Acitivities Log - USA
K2: $usd | L2: $usd
A3: No. | B3: Date | C3: Initiator | D3: Contact | E3: Company | F3: Contact Info | G3: City | H3: State | I3: Type | J3: Potential Projects | K3: Proposals Submitted | L3: Proposals Accepted | M3: Notes
A4: 1 | B4: 45976 | C4: Jim DesRoches | D4: Joseph Wong | E4: JWDA Architects | F4: aspousta@kennedywilson.com | G4: San Diego | H4: California | I4: RFP | J4: Kettner & Ash (mirror of Lindley) | K4: 700000 | L4: lost | M4: We were contacted by JWDA to review new project which is a mirror of the Lindley Project we designed for Toll Brothers that recently completed construction. Followup discussion with Matthew Geamon JWDA indicated Kennedy Wilson has chosen to back out of the deal for Kettner & Ash at this time - it may come back later, however KW currently has other priorities in their pipeline. I will followup with Andrew.
A5: 2 | B5: 46037 | C5: Jim DesRoches | D5: Craig Howard | E5: DBRDS Design Studio | F5: craig@dbrds.com | G5: San Diego | H5: California | I5: Meeting | J5: Riley St. San Diego, Northgate Sacramento | M5: Met at their office for 1650 Hotel Circle Cood meeting - they asked if we would be interested in some woodframe projects they we pursuing - we could expect RFP forthcoming
A6: 3 | B6: 46043 | C6: Jim DesRoches | D6: Craig Howard | E6: DBRDS Design Studio | F6: craig@dbrds.com | G6: San Diego | H6: California | I6: RFP | J6: Riley St. San Diego | K6: 50000 | M6: Followup from meeting of Jan 21
A7: 4 | B7: 46055 | C7: Jim DesRoches | D7: Craig Howard | E7: DBRDS Design Studio | F7: craig@dbrds.com | G7: San Diego | H7: California | I7: RFP | J7: Northgate Sacramento | K7: 95000 | L7: lost | M7: Followup from meeting of Jan 21, Spoke to Architect Apr 24 and he said the owner sold the site. It may still come back with new owner...but for now it is lost.
A8: 5 | B8: 46055 | C8: John Markulin | D8: Richard Bernstein | E8: CDA Architects | F8: richard.b@dikeakos.com | G8: Pima County | H8: Arizona | I8: RFP | J8: MR7 6 midrise | K8: 200000 | M8: Richard reached out for us to participate in a project they are pursuing in Arizona. He also asked us to increase our fee as our original fee was much lower than other consultants in the region.
A9: 6 | B9: 46055 | C9: John Markulin | D9: Richard Bernstein | E9: CDA Architects | F9: richard.b@dikeakos.com | G9: Pima County | H9: Arizona | I9: RFP | J9: MR7 6 highrise | K9: 295000 | M9: Richard reached out for us to participate in a project they are pursuing in Arizona. He also asked us to increase our fee as our original fee was much lower than other consultants in the region.
A10: 7 | B10: 46084 | C10: Jim DesRoches | D10: Mandy Serrano ; Greg Maclure; Greg Fall; Geoff Rubin;JT Barr; Matt Cook | E10: H + W Mechanical | F10: mandy@hwengr.com;gamcclure@leoadaly.com;greg.fall@cbre.com;geoff.rubin@kimley-horn.com;jtbarr@schmidtdesign.com;mcook@usa-nova.com | G10: San Diego | H10: California | I10: Meeting | J10: Will obtain list of project leads from this group. | M10: Mandy has invited us to join a BD Leads group that she manages - containing other consultants that compare and share leads for new work. We will be the only structural engineering firm in the group. Met with 4 others and discussed leads for new projects in public and private sector. This may be good group to help us break into public sector work. I plan to followup with some of the participants on new projects that were discussed. Am considering a roadtrip from San Diego to LA with Mandy to share leads and arrange meetings where we would share introductions.
A11: 8 | B11: 46085 | C11: Jim DesRoches | D11: Andrew Spousta | E11: Kennedy Wilson | F11: aspousta@kennedywilson.com | G11: San Diego | H11: California | I11: RFP | J11: Kettner & Ash (mirror of Lindley), Beverly Hills Tower, Woodframe project Santa Barbara | M11: Arranged to meet for lunch in San Diego. Andrew is previously with Toll Brothers who were bought by Kennedy Wilson. Followup to RFP to confirm status of Kettner & Ash - they are currently looking for equity party to share funding, Notified of two new projects that do not have Structural consultant yet, one in Santa Barbara and one in Beverly Hills. Andrew will send us RFP for both.
A12: 9 | B12: 46085 | C12: Jim DesRoches | D12: Geoff Rubin | E12: Kimley Horn | F12: geoff.rubin@kimley-horn.com | G12: San Diego | H12: California | I12: Email | J12: Large Indigenous Hotel Development | M12: Followup from Leads group meeting of Mar 3. Geoff expressed and interest in working with us on projects he has in pipeline. They are a turnkey engineering company but is lacking structural consulting. Could lead to some private sector and indigenous work. I sent him our project portfolio in the followup email.
A13: 10 | B13: 46086 | C13: Jim DesRoches | D13: Matthew Geaman | E13: JWDA Architects | F13: mgeaman@jwdainc.com | G13: San Diego | H13: California | I13: Meeting | J13: Kettner & Ash, New Mirka Tower | M13: Followup meeting with Matthew at JWDA office in person. - discussed Mirka lack of payment and strategy - JWDA intend to continue working expecting to eventually get paid. Mathew does not have much new coming up - some military work is keeping them busy. They hope Lindley II will start up soon. They will contact us if any new work breaks.
A14: 11 | B14: 46087 | C14: Jim DesRoches | D14: Paul Lamme | E14: Bosa Development | F14: plamme@bosadevelopment.com | G14: San Diego | H14: California | I14: Meeting | J14: 1st & Island | M14: Lunch meeting with Paul to discuss project status and new projects. 1st and Island will be on hold for now as they are focused on finishing their 8th & B project in San Diego, and 2 towers in Bellevue Wash. They said they have some changes coming on some of the suites in 1st & Island, and some VE expected of tower roof steel etc. Told Paul we would have a $35k extra to finish the project and maybe a bit more $$ if they make further changes - he had no issues with that.
A15: 12 | B15: 46087 | C15: Jim DesRoches | D15: Louis Nasr | E15: Bosa Development | F15: Lnasr@bosadevelopment.com | G15: San Diego | H15: California | I15: Meeting | J15: 1st & Island | M15: Stopped by 8th & B site to meet with Louis. Discussed GS dropping the ball on seismic instrumentation for the project. Bosa has spend $150k on equipment and expected to spend an additional $200k on installation. CSMIP is refusing to monitor the building since they have another Bosa project right next door that is already instrumented. It appears GS did not obtain approval from CSMIP during Peer review.....Bosa is not happy.
A16: 13 | B16: 46108 | C16: Jim DesRoches | D16: Paul Lamme | E16: Bosa Development | F16: plamme@bosadevelopment.com | G16: San Diego | H16: California | I16: Email | J16: 1st & Island | K16: 95000 | M16: Project is being revised and 3 floors added. We have been asked to proceed to compete the redesign. He acknowledged that this increases our scope to finish the project especially with respect to the peer review. We will charge extra $95000 total to perform the update and complete the project.
A17: 14 | B17: 46108 | C17: Jim DesRoches | D17: Ali Fattah | E17: City of San Diego | F17: afattah@sandiego.gov | G17: San Diego | H17: California | I17: Phone Call | J17: India & Beech (plan check), 611 Island Ave (peer review) | M17: Enquired about further plan check and peer review opportunities
A18: 15 | B18: 46114 | C18: John Markulin | D18: Richard Bernstein | E18: CDA Architects | F18: richard.b@dikeakos.com | G18: Tuscon | H18: Arizona | I18: RFP | J18: Trinity Townhomes | K18: 52000 | M18: Richard reached out for us to participate in a project they are pursuing in Arizona. He also asked us to increase our fee as our original fee was much lower than other consultants in the region.
A19: 16 | B19: 46136 | C19: Jim DesRoches | D19: Craig Howard | E19: DBRDS Design Studio | F19: craig@dbrds.com | G19: San Diego | H19: California | I19: Phone Call | J19: Riley St. San Diego, Northgate Sacramento Custon Homes | M19: Followup call with Craig - he said Sacramento project is lost as owner has sold the site, Riley St. is still a possibility as owner is still considering. He asked if we would consider doing custom homes. I told him we are not looking specifically for that type of work but would be happy to do it for him - he will send us proposals once it is time. He indicated that fees are not usully based on are and more one time required - they have a system and would be happy to assist us preparing a fee when the time comes.
A20: 17 | B20: 46136 | C20: Jim DesRoches | D20: Paul Lamme | E20: Bosa Development | F20: plamme@bosadevelopment.com | G20: San Diego | H20: California | I20: Phone Call | J20: Bellvue Peer Review, 1st & Island startup | M20: Paul indicated he was reviewing 1st & Island changes with city & FAA for height increase for confimation of approval before proceeding - we can expect kickoff meeting in about 2 weeks. I reminded him about Peer review on GS project in Bellvue - he indicated that it may be too late to change anything but he may still get us to do a review - I told him we would be happy to do that.
A22: TOTALS
A23: =A20 -> 17 | K23: =SUM(K4:K20) -> 1487000 | L23: =SUM(L4:L17) -> 0
A27: PENDING people to contact
C28: Jim DesRoches | D28: Chase Ronge | E28: MVE Architects
C29: Jim DesRoches | D29: Matt Maclarrand | E29: MVE Architects
C30: Jim DesRoches | D30: Duane Hagewood | E30: Carrier Johnson Culture | J30: 611 Island Avenue - Peer Review | M30: ask about status of project wrapping the storage building in Gaslamp - is it being revised (we are doing peer review). Also enquire about any new opportunities
C31: Jim DesRoches | D31: Adam Covington | E31: Greystar | M31: New opportunities? Matthew at JWDA indicated they are looking at a large woodframe project in LA.
C32: Jim DesRoches | D32: Mandy Serrano | E32: H + W Mechanical | M32: Arrange a BD road trip from San Diego to LA and share leads.
C33: Jim DesRoches | D33: Andrew Spousta | M33: Followup regarding further projects.

Sheet Alberta
A1: Business Development Acitivities Log - ALBERTA
A3: No. | B3: Date | C3: Initiator | D3: Contact | E3: Company | F3: Contact Info | G3: Location | H3: Type | I3: Potential Projects | J3: Proposals Submitted | K3: Proposals Accepted $ | L3: Notes
A4: 1 | B4: 46112 | C4: Islam Shabana | D4: Maurizio Capano | E4: Probus Management | F4: mcapano@probuspm.com | G4: Edmonton | H4: Email | L4: Maurizio is currently serving as Project Manager on several notable projects in Edmonton. I’ve had the opportunity to work with him on a couple of projects in the past, which helped establish a good connection. At the moment, he is fully committed to ongoing long-term projects and not taking on new work, but he was receptive to staying in touch. I plan to follow up with him again in a couple of months when his availability may open up.
A5: 2 | B5: 46114 | C5: Islam Shabana | D5: Steel Center of UofA | E5: University of Alberta | F5: vmazroue@ualberta.ca | G5: Edmonton | H5: Email | L5: Prepared a presentation on the technical challenges associated with the lateral design of high-rise buildings, with a focus on projects delivered by KOR in Alberta.
A6: 3 | B6: 46118 | C6: Islam Shabana | D6: MikeWoodLand | E6: Metafor Architecture | F6: mikew@metafor.studio | G6: Edmonton | H6: Email | I6: Fillmore Construction Industrial Bldg (design build), Vernon BC | L6: I gave Mike, a Principal at Metafor Architecture, a call to introduce KOR. He was receptive and open to meeting during the last week of April. I’ve followed up with an email proposing availability and am currently awaiting his confirmation. Islam followed up in an email and Mike asked to participate in a Design Build Project with Fillmore Construction for a small industrial building in Vernon.
A7: 4 | B7: 46118 | C7: Islam Shabana | D7: Ash Mahmoud | E7: Turn Group | F7: amahmoud@turngroup.ca | G7: Edmonton | H7: Email | I7: 990 Carling Ave, Ottawa, ON | J7: 620000 | L7: Ash, CEO of Turn Group (whom I’ve worked with previously), was receptive to reconnecting. I initiated a catch-up discussion on LinkedIn and followed up by sharing our company portfolio via email. We got RFP for 3 acres site in Ottawa that consists of 4 buildings (8-to-20 storeys). The project arhc is Arcadis.
A8: 5 | B8: 46120 | C8: Omar Alcazar | D8: Kerri Hagen | E8: A&H Steel | F8: kerrih@ah-steel.com | G8: Edmonton | H8: Meeting | L8: Kerri visisted KOR office in Vancouver to discuss potential ways of collaboration in BD in Edmonton and Vancouver.
A9: 6 | B9: 46125 | C9: Islam Shabana | D9: Adrian Benoit | E9: GEC Architecture | F9: adrian.benoit@gecarchitecture.com | G9: Edmonton | H9: Email | L9: Emailed Adrian to introduce KOR attaching an updated portfolio that shows a collection of residential, commercial, light industrial projects and asking for an intro meeting on May 7. Goal is to establish a GEC-KOR relationship.
A10: 7 | B10: 46136 | C10: Islam Shabana | D10: Tamer Elshimi | E10: Thurber | F10: telshimi@thurber.ca | G10: Edmonton | H10: Email | L10: I know Tamer who is a principal with Thurber. Thurber is heavily involved in institutional and other infrastructure work in Alberta. The goal was to set up an intro meeting to get their support thru early notification of opportunities that we can jump on.
A11: 8 | B11: 46150 | C11: Conor Murtagh | D11: Darrell Booth | E11: Cantiro Group | F11: dbooth@cantiro.ca | G11: Edmonton | H11: Other | J11: 18000 | L11: KOR had lunch with the BD team at Cantiro. They seemed open to including us on upcoming opportunities, particularly in the townhome sector. Mid-rise opportunities appear to already be committed.
A12: 9 | B12: 46149 | C12: Omar Alcazar | D12: Kerri Hagen | E12: PCL | F12: jpfleese@pcl.com | G12: Edmonton | H12: Presentation | L12: Kerri arranged a meet-and-greet with PCL Construction Edmonton. KOR presented at PCL on May 7, 2026.
A13: 10 | B13: 46149 | C13: Omar Alcazar | D13: Kerri Hagen | E13: Make Projects | F13: sfitzsimmons@makeprojects.ca | G13: Edmonton | H13: Other | L13: Kerri arranged a lunch meeting with Make Projects in Edmonton. We met with Shannon Fitzsimmons on May 7, 2026.
A14: 11 | B14: 46149 | C14: Omar Alcazar | D14: Kerri Hagen | E14: Ledcor | F14: lisette.sluser@ledcor.com | G14: Edmonton | H14: Presentation | L14: Kerri arranged a meet-and-greet with Ledcor Edmonton. The KOR team presented at Ledcor on May 7, 2026.
A15: 12 | B15: 46150 | C15: Islam Shabana | D15: Tamer Elshimi & Campell Chow | E15: Thurber | F15: telshimi@thurber.ca; cchow@thurber.ca | G15: Edmonton | H15: Email | L15: Follow up email after meeting at Thurber's Edmonton office on May 7.
A16: 13 | B16: 46150 | C16: Islam Shabana | D16: Adrian Benoit | E16: GEC Architecture | F16: adrian.benoit@gecarchitecture.com | G16: Edmonton | H16: Email | I16: Salisbury Village East, Site C | J16: 160000 | L16: Follow up email indicating our openness in supporting GEC in their reach in BC in exchange of his support in AB. Adrian asked to participate in a mixed use development in St Albert.
A17: 14 | B17: 46150 | C17: Conor Murtagh | D17: Ben Aitchison, Keith & Nicola | E17: Duke Management | F17: baitchison@dukemanagement.ca; keith@dukemanagement.ca; nicola@dukemanagement.ca | G17: Edmonton | H17: Meeting | I17: Kelowna Mill Site, Winnipeg Tower | L17: Met with Ben, Keith, Nicola at their office. Ben and Keith are leaders. We discussed Kelowna Mill project: expressed interest in potential use of mass timber for that project. I will followup with Example project (Pegasus San Diego). Also they have 20 story tower in Winnipeg wtih Arc Architects who are also the Exec Arch on the Kelowna Mills project. Will also followup with Arc regarding both projects.
A18: 15 | B18: 46150 | C18: Jim DesRoches | D18: Kerri Hagen | E18: A&H Steel | F18: kerrih@ah-steel.com | G18: Edmonton | H18: Email | L18: Followed up and sent her example of Quantity takeoff report for Heatherlands. Asked if she could help confirm rebar densities. Perhaps using Richards and Drake as an example.
A19: 16 | B19: 46153 | C19: Islam Shabana | D19: Joe Edbeid | E19: JLL real estate | F19: joe.ebeid@jll.com | G19: Edmonton | H19: Meeting | L19: Islam met with Joe Ebeid (Senior project manager at JLL). Joe will consider us for upcoming work whenever possible and sent us a client list to contact.
A20: 17 | B20: 46153 | C20: Islam Shabana | D20: Lisette Sluser | E20: Ledcor | F20: lisette.sluser@ledcor.com | G20: Edmonton | H20: Email | L20: Follow up email after presentation at Ledcor Edmonton. During the presentation, Ledcor expressed interest in reviewing our portfolio, particularly light industrial projects involving tilt-up construction. Islam prepared and sent the requested portfolio and qualifications on.
A21: 18 | B21: 46153 | C21: Islam Shabana | D21: Ben Aitchison, Keith & Nicola | E21: Duke Management | F21: baitchison@dukemanagement.ca; keith@dukemanagement.ca; nicola@dukemanagement.ca | G21: Edmonton | H21: Email | L21: Follow up email after meeting with Duke at their office in St Albert on May 8, inlcuding KOR's portfolio.
A22: 19 | B22: 46153 | C22: Islam Shabana | D22: Shannon Fitzsimmons | E22: Make Projects | F22: sfitzsimmons@makeprojects.ca | G22: Edmonton | H22: Email | L22: Follow up email after lunch with Shannon in Edmonton on May 7. Shannon asked to see a portfolio showing commercial jobs along with our qualifications and Islam prepared and sent the requested info. She also mentioned ther might be opportunities on smaller jobs in the near future.
A23: 20 | B23: 46153 | C23: Jim DesRoches | D23: Ben Aitchison, Keith & Nicola | E23: Duke Management | F23: baitchison@dukemanagement.ca; keith@dukemanagement.ca; nicola@dukemanagement.ca | G23: Edmonton | H23: Email | I23: Kelowna Mill Site, Winnipeg Tower | L23: Followup email sent to all 3 at Duke highlighting our mass timber work - featuring Pegasus project in San Diego. Also indicated that we are currently working on Suttom place Hotel in Winnipeg.
A24: 21 | B24: 46156 | C24: Jim DesRoches | D24: Shannon Fitzsimmons | E24: Make Projects | F24: sfitzsimmons@makeprojects.ca | G24: Edmonton | H24: Email | L24: Followed up and sent her example of Quantity takeoff report for Heatherlands. She indicated they were starting to provide Quantity Estimating Services - offered to collaborate on projects with here and supplement her estimating services in this manner. Goal would be to get in early on new projects and get selected to complete final design.
A25: 22 | B25: 46157 | C25: Islam Shabana | D25: Ian Evans | E25: HSEA Architecture | F25: ievans@hsea.ca | G25: Edmonton | H25: Email | L25: Checking in email - I worked with Ian on multiple projects in the past and wanted to hint my return to KOR in an effort to solicit business.
A26: 23 | B26: 46161 | C26: Islam Shabana | D26: Michael Sheehan & Stacy Kasnot | E26: L7 Architecture | F26: m.sheehan@l7arch.ca; s.kasnot@l7arch.ca | G26: Edmonton | H26: Email | L26: Intro email - contact info from Joe Ebeid @ JLL. They asked to meet at theif office on June 4 or 5 at 10 am. The goal is to setup a meeting and build a relationship with L7.
A27: 24 | B27: 46161 | C27: Islam Shabana | D27: Joanne Smith | E27: Sahuri + Partners Architecture | F27: Joanne.Smith@sahuri.com | G27: Calgary | H27: Email | L27: Intro email - contact info from Joe Ebeid @ JLL. The goal is to setup a meeting in Calgary towards mid-June.
A28: 25 | B28: 46161 | C28: Islam Shabana | D28: Anuj Gupta | E28: Anu Developements | F28: anuj@anudevelopments.ca | G28: Edmonton | H28: Email | L28: Intro email and request to meet and offer structural engineering services.
A29: 26 | B29: 46161 | C29: Islam Shabana | D29: Tyler Dixon & Tai Ziola | E29: Dialog Design | F29: tdixon@dialogdesign.ca; tziola@dialogdesign.ca | G29: Edmonton | H29: Email | L29: Intro email and request to meet and offer structural engineering services. They suggested to meet in July.
A30: 27 | B30: 46161 | C30: Islam Shabana | D30: Sameer Remtulla | E30: Deveraux Group | F30: sremtulla@deveraux.ca | G30: Edmonton | H30: Email | L30: Sameer is a Senior VP at Deveraux Group. I did a couple of designs for Deveraux in the past and emailed him to see their Openness to give KOR work.
A31: 28 | B31: 46161 | C31: Islam Shabana | D31: David Taylor | E31: PK Developments | F31: dave@pkdevelopments.ca | G31: Edmonton | H31: Email | L31: David is the president of PK Developments who are very active in mid-rise construction across Alberta. They seem to have work in SK and BC as well. The goal is to setup a meeting and introduce KOR and try to solicit business.
A32: 29 | B32: 46162 | C32: Islam Shabana | D32: Peter Streith | E32: S2 Architecture | F32: p.streith@s2architecture.com | G32: Edmonton | H32: Email | L32: Peter is a principal at S2 Edmonton office. I sent him an into email and asked if he is open to meet.
A33: 30 | B33: 46162 | C33: Omar Alcazar | D33: Sukhi Raj | E33: RBI group | G33: Edmonton | H33: Phone Call | I33: wood Frame/Hotels | L33: Sukhi is the owner of RBI Group, he is going to send me drawigns for a new wood frame
A34: 30 | B34: 46163 | C34: Omar Alcazar | D34: Kerri Hagen | E34: A&H Steel | F34: kerrih@ah-steel.com | G34: Edmonton | H34: Email | L34: Kerri will try to set up more meeting with GC's for the week of June 23rd
A35: 32 | B35: 46167 | C35: Omar Alcazar | D35: Lisette Sluser | E35: Ledcor | G35: Edmotont | H35: Email | L35: We got invited to the Ledcor client appriciation event on June 23rd - Islam will be attending
J37: =SUM(J4:J36) -> 798000 | K37: =SUM(K4:K36) -> 0
A40: PENDING people to contact | D40: Company | E40: Worked with? | F40: Type | G40: Remark
A41: Kyle Russell & Michael Vercillo | D41: PCL Construction | E41: Yes | F41: Contractor
A42: Shane Heintz | D42: Graham | E42: Yes | F42: Contractor
A43: Davis Wajda | D43: Bird Construction | F43: Contractor
A45: Ken Froner & Asma Javed | D45: START Architecture | E45: Yes | F45: Arch | G45: ** JM to inroduce to dialog? they're well established here and we might have already collaborated a lot with them
...

Sheet Okanagan; BC Interior
A1: Business Development Acitivities Log - OKANAGAN; BC INTERIOR
A3: No. | B3: Date | C3: Initiator | D3: Contact | E3: Company | F3: Contact Info | G3: Location | H3: Type | I3: Potential Projects | J3: Proposals Submitted | K3: Proposals Accepted $ | L3: Notes
A4: 1 | B4: 45926 | C4: Conor Murtagh | D4: Sarb Saba | E4: Saba Construction | F4: hayers1@live.com | G4: Kelowna | H4: Meeting | L4: Conor, JM, Jim & Simon met Sarb for coffee in Kelowna
A5: 2 | B5: 45926 | C5: Conor Murtagh | D5: Jim Meiklejohn | E5: Meiklejohn Architects | F5: jim-mai@shaw.ca | G5: kelowna | H5: Meeting | I5: Sutton Crescent | J5: 110000 | L5: Conor, JM, Jim & Simon met Jim,Shirley, Stoke & Collin for lunch in Kelowna
A6: 3 | B6: 45926 | C6: Conor Murtagh | D6: Jeff Nishimura | E6: Greenstone Developments | F6: jeff@greenstonedevelopments.ca | G6: Kelowna | H6: Meeting | L6: Conor, JM, & Jim met Jeff, Tyler, Mike, & Shawn for drinks in Kelowna
A7: 4 | B7: 45968 | C7: Conor Murtagh | D7: Aaron Gietema | E7: Holar Developments | F7: aaron.gietema@holardevelopments.com | G7: Vernon | H7: Meeting | I7: Kelowna Mill Project | J7: 150000 | L7: Conor & Jim met Aaron for coffee.
A8: 5 | B8: 45968 | C8: Conor Murtagh | D8: Paul Schuster/ Inder Pabla | E8: Novation Architecture | F8: paul@novationarchitecture.com / inder@novationarchitecture.com | G8: Kelowna | H8: Meeting | I8: 945 Rutland RD | J8: 40000 | K8: 40000 | L8: Conor & Jim visited Novation's office
A9: 6 | B9: 45968 | C9: Conor Murtagh | D9: Usman Aziz | E9: NewTown Architecture | F9: usman@newtownservices.net | G9: Kelowna | H9: Meeting | L9: Conor & Jim visited NewTowns's office.
A10: 7 | B10: 46002 | C10: Conor Murtagh | D10: Jonathon Silcock | E10: Denciti Developments | F10: jsilcock@denciti.ca | G10: Kelowna | H10: Event | L10: Conor met Jonathon at UDI Okanagan Holiday Reception
A11: 8 | B11: 46006 | C11: Conor Murtagh | D11: Alisia Strautins | E11: Traine | F11: astrautins@traine.ca | G11: Kelowna | H11: Meeting | I11: 380 Taunton Rd, Whitby, Ontario RJC review & 150 Lynden RD, Brantford, Ontario | J11: 125000 | K11: 15000 | L11: Conor & Jim met Alisia for lunch
A12: 9 | B12: 46031 | C12: Conor Murtagh | D12: Sean Wilson | E12: Ridge North America | F12: wilson@ridgenorthamerica.ca | H12: Phone Call | L12: Organised meeting but fell through. Rory working on another project with him now.
A13: 10 | B13: 46042 | C13: Conor Murtagh | D13: Matt Johnston | E13: Lime Architecture | F13: matt@limearchitecture | G13: Kelowna | H13: Meeting | L13: Conor & Jim visited Lime's office
A14: 11 | B14: 46042 | C14: Conor Murtagh | D14: Ryan Wheeler | E14: Wilden | F14: ryan@wilden.ca | G14: Kelowna | H14: Meeting | I14: Cattail Pond | J14: 36000 | K14: 36000 | L14: Conor & Jim visited Wilden's showroom
A15: 12 | B15: 46104 | C15: Conor Murtagh | D15: Mark Aquilon | E15: Michael Green Architecture | F15: mark@mgaarch.ca | G15: Kelowna | H15: Meeting | L15: Conor & Simon visited MGA's office
A16: 13 | C16: Omar Alcazar | D16: Allan Lal | E16: Mundi hotels | F16: AL@mundiconstruction.ca | H16: Other | I16: Potential Hotels
A17: 14 | B17: 46148 | C17: Conor Murtagh | D17: Ian O Donnell | E17: Westrich Pacific | F17: ian@westrichpacific.com | G17: Edmonton | H17: Meeting | L17: Arranged lunch to introduce Kor to Edmonton.
A18: 15 | B18: 46150 | C18: Conor Murtagh | D18: Nicola Dolan | E18: Duke Management | F18: Nicola@dukemanagement.ca | G18: Edmonton | H18: Meeting | I18: Kelowna Mill Project, Winnipeg Tower | L18: Arranged office visit to introduce Kor to Edmonton. Islam and Jim met with Ben Aitchison (Construction manager). They're open to considering us on upcoming opportunities including Kelowna Mill, 6-storey wood resi in Edmonton, and a tower in downtown Winnipeg.
A19: TOTALS
A20: =A18 -> 15 | J20: =SUM(J4:J19) -> 461000 | K20: =SUM(K4:K19) -> 91000
A25: PENDING people to contact

Sheet Eastern Canada
A1: Business Development Acitivities Log - EASTERN CANADA
A3: No. | B3: Date | C3: Initiator | D3: Contact | E3: Company | F3: Contact Info | G3: Location | H3: Type | I3: Potential Projects | J3: Proposals Submitted | K3: Proposals Accepted $ | L3: Notes
A4: 1 | J4: 0.01 | K4: 0
A6: TOTALS
A7: =A4 -> 1 | J7: =SUM(J4:J6) -> 0.01 | K7: =SUM(K4:K6) -> 0

Sheet contact type
A1: Meeting
A2: Phone Call
A3: Email
A4: Event
A5: Presentation
A6: Other
A7: RFP
